INFO:     127.0.0.1:50906 - "POST /subscribe HTTP/1.1" 500 Internal Server Error
ERROR:    Exception in ASGI application
Traceback (most recent call last):
  File "/Users/user/Documents/GitHub/gliner-medical-finetuning/venv/lib/python3.13/site-packages/urllib3/connection.py", line 198, in _new_conn
    sock = connection.create_connection(
        (self._dns_host, self.port),
    ...<2 lines>...
        socket_options=self.socket_options,
    )
  File "/Users/user/Documents/GitHub/gliner-medical-finetuning/venv/lib/python3.13/site-packages/urllib3/util/connection.py", line 60, in create_connection
    for res in socket.getaddrinfo(host, port, family, socket.SOCK_STREAM):
               ~~~~~~~~~~~~~~~~~~^^^^^^^^^^^^^^^^^^^^^^^^^^^^^^^^^^^^^^^^
  File "/opt/homebrew/Cellar/python@3.13/3.13.7/Frameworks/Python.framework/Versions/3.13/lib/python3.13/socket.py", line 977, in getaddrinfo
    for res in _socket.getaddrinfo(host, port, family, type, proto, flags):
               ~~~~~~~~~~~~~~~~~~~^^^^^^^^^^^^^^^^^^^^^^^^^^^^^^^^^^^^^^^^
socket.gaierror: [Errno 8] nodename nor servname provided, or not known

The above exception was the direct cause of the following exception:

Traceback (most recent call last):
  File "/Users/user/Documents/GitHub/gliner-medical-finetuning/venv/lib/python3.13/site-packages/urllib3/connectionpool.py", line 787, in urlopen
    response = self._make_request(
        conn,
    ...<10 lines>...
        **response_kw,
    )
  File "/Users/user/Documents/GitHub/gliner-medical-finetuning/venv/lib/python3.13/site-packages/urllib3/connectionpool.py", line 493, in _make_request
    conn.request(
    ~~~~~~~~~~~~^
        method,
        ^^^^^^^
    ...<6 lines>...
        enforce_content_length=enforce_content_length,
        ^^^^^^^^^^^^^^^^^^^^^^^^^^^^^^^^^^^^^^^^^^^^^^
    )
    ^
  File "/Users/user/Documents/GitHub/gliner-medical-finetuning/venv/lib/python3.13/site-packages/urllib3/connection.py", line 494, in request
    self.endheaders()
    ~~~~~~~~~~~~~~~^^
  File "/opt/homebrew/Cellar/python@3.13/3.13.7/Frameworks/Python.framework/Versions/3.13/lib/python3.13/http/client.py", line 1333, in endheaders
    self._send_output(message_body, encode_chunked=encode_chunked)
    ~~~~~~~~~~~~~~~~~^^^^^^^^^^^^^^^^^^^^^^^^^^^^^^^^^^^^^^^^^^^^^
  File "/opt/homebrew/Cellar/python@3.13/3.13.7/Frameworks/Python.framework/Versions/3.13/lib/python3.13/http/client.py", line 1093, in _send_output
    self.send(msg)
    ~~~~~~~~~^^^^^
  File "/opt/homebrew/Cellar/python@3.13/3.13.7/Frameworks/Python.framework/Versions/3.13/lib/python3.13/http/client.py", line 1037, in send
    self.connect()
    ~~~~~~~~~~~~^^
  File "/Users/user/Documents/GitHub/gliner-medical-finetuning/venv/lib/python3.13/site-packages/urllib3/connection.py", line 325, in connect
    self.sock = self._new_conn()
                ~~~~~~~~~~~~~~^^
  File "/Users/user/Documents/GitHub/gliner-medical-finetuning/venv/lib/python3.13/site-packages/urllib3/connection.py", line 205, in _new_conn
    raise NameResolutionError(self.host, self, e) from e
urllib3.exceptions.NameResolutionError: <urllib3.connection.HTTPConnection object at 0x10fc56510>: Failed to resolve 'keycloak' ([Errno 8] nodename nor servname provided, or not known)

The above exception was the direct cause of the following exception:

Traceback (most recent call last):
  File "/Users/user/Documents/GitHub/gliner-medical-finetuning/venv/lib/python3.13/site-packages/requests/adapters.py", line 644, in send
    resp = conn.urlopen(
        method=request.method,
    ...<9 lines>...
        chunked=chunked,
    )
  File "/Users/user/Documents/GitHub/gliner-medical-finetuning/venv/lib/python3.13/site-packages/urllib3/connectionpool.py", line 841, in urlopen
    retries = retries.increment(
        method, url, error=new_e, _pool=self, _stacktrace=sys.exc_info()[2]
    )
  File "/Users/user/Documents/GitHub/gliner-medical-finetuning/venv/lib/python3.13/site-packages/urllib3/util/retry.py", line 519, in increment
    raise MaxRetryError(_pool, url, reason) from reason  # type: ignore[arg-type]
    ^^^^^^^^^^^^^^^^^^^^^^^^^^^^^^^^^^^^^^^^^^^^^^^^^^^
urllib3.exceptions.MaxRetryError: HTTPConnectionPool(host='keycloak', port=8090): Max retries exceeded with url: /realms/master/protocol/openid-connect/token (Caused by NameResolutionError("<urllib3.connection.HTTPConnection object at 0x10fc56510>: Failed to resolve 'keycloak' ([Errno 8] nodename nor servname provided, or not known)"))

During handling of the above exception, another exception occurred:

Traceback (most recent call last):
  File "/Users/user/Documents/GitHub/gliner-medical-finetuning/venv/lib/python3.13/site-packages/uvicorn/protocols/http/h11_impl.py", line 403, in run_asgi
    result = await app(  # type: ignore[func-returns-value]
             ^^^^^^^^^^^^^^^^^^^^^^^^^^^^^^^^^^^^^^^^^^^^^^
        self.scope, self.receive, self.send
        ^^^^^^^^^^^^^^^^^^^^^^^^^^^^^^^^^^^
    )
    ^
  File "/Users/user/Documents/GitHub/gliner-medical-finetuning/venv/lib/python3.13/site-packages/uvicorn/middleware/proxy_headers.py", line 60, in __call__
    return await self.app(scope, receive, send)
           ^^^^^^^^^^^^^^^^^^^^^^^^^^^^^^^^^^^^
  File "/Users/user/Documents/GitHub/gliner-medical-finetuning/venv/lib/python3.13/site-packages/fastapi/applications.py", line 1054, in __call__
    await super().__call__(scope, receive, send)
  File "/Users/user/Documents/GitHub/gliner-medical-finetuning/venv/lib/python3.13/site-packages/starlette/applications.py", line 113, in __call__
    await self.middleware_stack(scope, receive, send)
  File "/Users/user/Documents/GitHub/gliner-medical-finetuning/venv/lib/python3.13/site-packages/starlette/middleware/errors.py", line 186, in __call__
    raise exc
  File "/Users/user/Documents/GitHub/gliner-medical-finetuning/venv/lib/python3.13/site-packages/starlette/middleware/errors.py", line 164, in __call__
    await self.app(scope, receive, _send)
  File "/Users/user/Documents/GitHub/gliner-medical-finetuning/venv/lib/python3.13/site-packages/starlette/middleware/cors.py", line 93, in __call__
    await self.simple_response(scope, receive, send, request_headers=headers)
  File "/Users/user/Documents/GitHub/gliner-medical-finetuning/venv/lib/python3.13/site-packages/starlette/middleware/cors.py", line 144, in simple_response
    await self.app(scope, receive, send)
  File "/Users/user/Documents/GitHub/gliner-medical-finetuning/venv/lib/python3.13/site-packages/starlette/middleware/exceptions.py", line 63, in __call__
    await wrap_app_handling_exceptions(self.app, conn)(scope, receive, send)
  File "/Users/user/Documents/GitHub/gliner-medical-finetuning/venv/lib/python3.13/site-packages/starlette/_exception_handler.py", line 53, in wrapped_app
    raise exc
  File "/Users/user/Documents/GitHub/gliner-medical-finetuning/venv/lib/python3.13/site-packages/starlette/_exception_handler.py", line 42, in wrapped_app
    await app(scope, receive, sender)
  File "/Users/user/Documents/GitHub/gliner-medical-finetuning/venv/lib/python3.13/site-packages/starlette/routing.py", line 716, in __call__
    await self.middleware_stack(scope, receive, send)
  File "/Users/user/Documents/GitHub/gliner-medical-finetuning/venv/lib/python3.13/site-packages/starlette/routing.py", line 736, in app
    await route.handle(scope, receive, send)
  File "/Users/user/Documents/GitHub/gliner-medical-finetuning/venv/lib/python3.13/site-packages/starlette/routing.py", line 290, in handle
    await self.app(scope, receive, send)
  File "/Users/user/Documents/GitHub/gliner-medical-finetuning/venv/lib/python3.13/site-packages/starlette/routing.py", line 78, in app
    await wrap_app_handling_exceptions(app, request)(scope, receive, send)
  File "/Users/user/Documents/GitHub/gliner-medical-finetuning/venv/lib/python3.13/site-packages/starlette/_exception_handler.py", line 53, in wrapped_app
    raise exc
  File "/Users/user/Documents/GitHub/gliner-medical-finetuning/venv/lib/python3.13/site-packages/starlette/_exception_handler.py", line 42, in wrapped_app
    await app(scope, receive, sender)
  File "/Users/user/Documents/GitHub/gliner-medical-finetuning/venv/lib/python3.13/site-packages/starlette/routing.py", line 75, in app
    response = await f(request)
               ^^^^^^^^^^^^^^^^
  File "/Users/user/Documents/GitHub/gliner-medical-finetuning/venv/lib/python3.13/site-packages/fastapi/routing.py", line 302, in app
    raw_response = await run_endpoint_function(
                   ^^^^^^^^^^^^^^^^^^^^^^^^^^^^
    ...<3 lines>...
    )
    ^
  File "/Users/user/Documents/GitHub/gliner-medical-finetuning/venv/lib/python3.13/site-packages/fastapi/routing.py", line 213, in run_endpoint_function
    return await dependant.call(**values)
           ^^^^^^^^^^^^^^^^^^^^^^^^^^^^^^
  File "/Users/user/Documents/GitHub/gliner-medical-finetuning/api/app.py", line 123, in subscribe
    admin_token = get_admin_token()
  File "/Users/user/Documents/GitHub/gliner-medical-finetuning/api/app.py", line 39, in get_admin_token
    response = requests.post(token_url, data=data)
  File "/Users/user/Documents/GitHub/gliner-medical-finetuning/venv/lib/python3.13/site-packages/requests/api.py", line 115, in post
    return request("post", url, data=data, json=json, **kwargs)
  File "/Users/user/Documents/GitHub/gliner-medical-finetuning/venv/lib/python3.13/site-packages/requests/api.py", line 59, in request
    return session.request(method=method, url=url, **kwargs)
           ~~~~~~~~~~~~~~~^^^^^^^^^^^^^^^^^^^^^^^^^^^^^^^^^^
  File "/Users/user/Documents/GitHub/gliner-medical-finetuning/venv/lib/python3.13/site-packages/requests/sessions.py", line 589, in request
    resp = self.send(prep, **send_kwargs)
  File "/Users/user/Documents/GitHub/gliner-medical-finetuning/venv/lib/python3.13/site-packages/requests/sessions.py", line 703, in send
    r = adapter.send(request, **kwargs)
  File "/Users/user/Documents/GitHub/gliner-medical-finetuning/venv/lib/python3.13/site-packages/requests/adapters.py", line 677, in send
    raise ConnectionError(e, request=request)
requests.exceptions.ConnectionError: HTTPConnectionPool(host='keycloak', port=8090): Max retries exceeded with url: /realms/master/protocol/openid-connect/token (Caused by NameResolutionError("<urllib3.connection.HTTPConnection object at 0x10fc56510>: Failed to resolve 'keycloak' ([Errno 8] nodename nor servname provided, or not known)"))